<?xml version="1.0" ?>
<!-- =================================================================================== -->
<!-- |    This document was autogenerated by xacro from src/jackal_ar4_description/urdf/jackal_ar4.urdf.xacro | -->
<!-- |    EDITING THIS FILE BY HAND IS NOT RECOMMENDED                                 | -->
<!-- =================================================================================== -->
<robot name="jackal_ar4" xmlns:gz="http://gazebosim.org/schema">
  <material name="clearpath_dark_grey">
    <color rgba="0.2 0.2 0.2 1.0"/>
  </material>
  <material name="clearpath_medium_grey">
    <color rgba="0.6 0.6 0.6 1.0"/>
  </material>
  <material name="clearpath_light_grey">
    <color rgba="0.8 0.8 0.8 1.0"/>
  </material>
  <material name="clearpath_yellow">
    <color rgba="0.8 0.8 0.0 1.0"/>
  </material>
  <material name="clearpath_black">
    <color rgba="0.15 0.15 0.15 1.0"/>
  </material>
  <material name="clearpath_white">
    <color rgba="1.0 1.0 1.0 1.0"/>
  </material>
  <material name="clearpath_red">
    <color rgba="1.0 0.0 0.0 1.0"/>
  </material>
  <material name="clearpath_aluminum">
    <color rgba="0.5 0.5 0.5 1"/>
  </material>
  <material name="clearpath_plastic">
    <color rgba="0.1 0.1 0.1   1"/>
  </material>
  <link name="base_link"/>
  <joint name="base_link_joint" type="fixed">
    <origin rpy="0 0 0" xyz="0 0 0"/>
    <parent link="base_link"/>
    <child link="chassis_link"/>
  </joint>
  <link name="chassis_link">
    <visual>
      <origin rpy="1.5707963267948966 0 1.5707963267948966" xyz="0 0 -0.0655"/>
      <geometry>
        <mesh filename="package://clearpath_platform_description/meshes/j100/j100_base.stl"/>
      </geometry>
      <material name="clearpath_yellow"/>
    </visual>
    <collision>
      <origin xyz="0 0 0.092"/>
      <geometry>
        <box size="0.42 0.31 0.184"/>
      </geometry>
    </collision>
    <inertial>
      <origin rpy="0 0 0" xyz="0.012  0.002 0.067"/>
      <mass value="16.523"/>
      <inertia ixx="0.3136" ixy="-0.0008" ixz="0.0164" iyy="0.3922" iyz="-0.0009" izz="0.4485"/>
    </inertial>
  </link>
  <link name="front_left_wheel_link">
    <visual>
      <origin rpy="1.5707963267948966 0 0" xyz="0 0 0"/>
      <geometry>
        <mesh filename="package://clearpath_platform_description/meshes/j100/wheels/outdoor.stl"/>
      </geometry>
      <material name="clearpath_black"/>
    </visual>
    <collision>
      <origin rpy="1.5707963267948966 0 0" xyz="0 0 0"/>
      <geometry>
        <cylinder length="0.04" radius="0.098"/>
      </geometry>
    </collision>
    <inertial>
      <origin rpy="0 0 0" xyz="0 0 0"/>
      <mass value="0.477"/>
      <inertia ixx="0.0013" ixy="0" ixz="0" iyy="0.0024" iyz="0" izz="0.0013"/>
    </inertial>
  </link>
  <gazebo>
    <plugin filename="libgz-sim-wheel-slip-system.so" name="gz::sim::systems::WheelSlip">
      <wheel link_name="front_left_wheel_link">
        <slip_compliance_lateral>1.0</slip_compliance_lateral>
        <slip_compliance_longitudinal>1.0</slip_compliance_longitudinal>
        <wheel_normal_force>40</wheel_normal_force>
        <wheel_radius>0.098</wheel_radius>
      </wheel>
    </plugin>
  </gazebo>
  <gazebo reference="front_left_wheel_link">
    <material>Gazebo/DarkGrey</material>
    <selfCollide>false</selfCollide>
    <mu1 value="0.5"/>
    <mu2 value="0.5"/>
    <fdir1 value="1 0 0"/>
  </gazebo>
  <joint name="front_left_wheel_joint" type="continuous">
    <parent link="chassis_link"/>
    <child link="front_left_wheel_link"/>
    <origin rpy="0 0 0" xyz="0.131 0.187795 0.0345"/>
    <axis xyz="0 1 0"/>
  </joint>
  <link name="front_right_wheel_link">
    <visual>
      <origin rpy="1.5707963267948966 0 0" xyz="0 0 0"/>
      <geometry>
        <mesh filename="package://clearpath_platform_description/meshes/j100/wheels/outdoor.stl"/>
      </geometry>
      <material name="clearpath_black"/>
    </visual>
    <collision>
      <origin rpy="1.5707963267948966 0 0" xyz="0 0 0"/>
      <geometry>
        <cylinder length="0.04" radius="0.098"/>
      </geometry>
    </collision>
    <inertial>
      <origin rpy="0 0 0" xyz="0 0 0"/>
      <mass value="0.477"/>
      <inertia ixx="0.0013" ixy="0" ixz="0" iyy="0.0024" iyz="0" izz="0.0013"/>
    </inertial>
  </link>
  <gazebo>
    <plugin filename="libgz-sim-wheel-slip-system.so" name="gz::sim::systems::WheelSlip">
      <wheel link_name="front_right_wheel_link">
        <slip_compliance_lateral>1.0</slip_compliance_lateral>
        <slip_compliance_longitudinal>1.0</slip_compliance_longitudinal>
        <wheel_normal_force>40</wheel_normal_force>
        <wheel_radius>0.098</wheel_radius>
      </wheel>
    </plugin>
  </gazebo>
  <gazebo reference="front_right_wheel_link">
    <material>Gazebo/DarkGrey</material>
    <selfCollide>false</selfCollide>
    <mu1 value="0.5"/>
    <mu2 value="0.5"/>
    <fdir1 value="1 0 0"/>
  </gazebo>
  <joint name="front_right_wheel_joint" type="continuous">
    <parent link="chassis_link"/>
    <child link="front_right_wheel_link"/>
    <origin rpy="0 0 0" xyz="0.131 -0.187795 0.0345"/>
    <axis xyz="0 1 0"/>
  </joint>
  <link name="rear_left_wheel_link">
    <visual>
      <origin rpy="1.5707963267948966 0 0" xyz="0 0 0"/>
      <geometry>
        <mesh filename="package://clearpath_platform_description/meshes/j100/wheels/outdoor.stl"/>
      </geometry>
      <material name="clearpath_black"/>
    </visual>
    <collision>
      <origin rpy="1.5707963267948966 0 0" xyz="0 0 0"/>
      <geometry>
        <cylinder length="0.04" radius="0.098"/>
      </geometry>
    </collision>
    <inertial>
      <origin rpy="0 0 0" xyz="0 0 0"/>
      <mass value="0.477"/>
      <inertia ixx="0.0013" ixy="0" ixz="0" iyy="0.0024" iyz="0" izz="0.0013"/>
    </inertial>
  </link>
  <gazebo>
    <plugin filename="libgz-sim-wheel-slip-system.so" name="gz::sim::systems::WheelSlip">
      <wheel link_name="rear_left_wheel_link">
        <slip_compliance_lateral>1.0</slip_compliance_lateral>
        <slip_compliance_longitudinal>1.0</slip_compliance_longitudinal>
        <wheel_normal_force>40</wheel_normal_force>
        <wheel_radius>0.098</wheel_radius>
      </wheel>
    </plugin>
  </gazebo>
  <gazebo reference="rear_left_wheel_link">
    <material>Gazebo/DarkGrey</material>
    <selfCollide>false</selfCollide>
    <mu1 value="0.5"/>
    <mu2 value="0.5"/>
    <fdir1 value="1 0 0"/>
  </gazebo>
  <joint name="rear_left_wheel_joint" type="continuous">
    <parent link="chassis_link"/>
    <child link="rear_left_wheel_link"/>
    <origin rpy="0 0 0" xyz="-0.131 0.187795 0.0345"/>
    <axis xyz="0 1 0"/>
  </joint>
  <link name="rear_right_wheel_link">
    <visual>
      <origin rpy="1.5707963267948966 0 0" xyz="0 0 0"/>
      <geometry>
        <mesh filename="package://clearpath_platform_description/meshes/j100/wheels/outdoor.stl"/>
      </geometry>
      <material name="clearpath_black"/>
    </visual>
    <collision>
      <origin rpy="1.5707963267948966 0 0" xyz="0 0 0"/>
      <geometry>
        <cylinder length="0.04" radius="0.098"/>
      </geometry>
    </collision>
    <inertial>
      <origin rpy="0 0 0" xyz="0 0 0"/>
      <mass value="0.477"/>
      <inertia ixx="0.0013" ixy="0" ixz="0" iyy="0.0024" iyz="0" izz="0.0013"/>
    </inertial>
  </link>
  <gazebo>
    <plugin filename="libgz-sim-wheel-slip-system.so" name="gz::sim::systems::WheelSlip">
      <wheel link_name="rear_right_wheel_link">
        <slip_compliance_lateral>1.0</slip_compliance_lateral>
        <slip_compliance_longitudinal>1.0</slip_compliance_longitudinal>
        <wheel_normal_force>40</wheel_normal_force>
        <wheel_radius>0.098</wheel_radius>
      </wheel>
    </plugin>
  </gazebo>
  <gazebo reference="rear_right_wheel_link">
    <material>Gazebo/DarkGrey</material>
    <selfCollide>false</selfCollide>
    <mu1 value="0.5"/>
    <mu2 value="0.5"/>
    <fdir1 value="1 0 0"/>
  </gazebo>
  <joint name="rear_right_wheel_joint" type="continuous">
    <parent link="chassis_link"/>
    <child link="rear_right_wheel_link"/>
    <origin rpy="0 0 0" xyz="-0.131 -0.187795 0.0345"/>
    <axis xyz="0 1 0"/>
  </joint>
  <!-- ROS2 controls -->
  <ros2_control name="j100_hardware" type="system">
    <hardware>
      <plugin>clearpath_hardware_interfaces/J100Hardware</plugin>
    </hardware>
    <joint name="front_left_wheel_joint">
      <command_interface name="velocity"/>
      <state_interface name="position"/>
      <state_interface name="velocity"/>
    </joint>
    <joint name="front_right_wheel_joint">
      <command_interface name="velocity"/>
      <state_interface name="position"/>
      <state_interface name="velocity"/>
    </joint>
  </ros2_control>
  <link name="imu_0_link">
    <inertial>
      <mass value="0.001"/>
      <origin rpy="0 0 0" xyz="0 0 0"/>
      <inertia ixx="1e-09" ixy="0.0" ixz="0.0" iyy="1e-09" iyz="0.0" izz="1e-09"/>
    </inertial>
  </link>
  <joint name="imu_joint" type="fixed">
    <parent link="chassis_link"/>
    <child link="imu_0_link"/>
  </joint>
  <gazebo reference="imu_0_link">
    <sensor name="imu_0" type="imu">
      <always_on>true</always_on>
      <update_rate>50</update_rate>
      <visualize>true</visualize>
      <gz_frame_id>imu_0_link</gz_frame_id>
      <topic>/sensors/imu_0/data_raw</topic>
    </sensor>
  </gazebo>
  <link name="gps_0_link">
    <visual>
      <geometry>
        <cylinder length="0.016" radius="0.026"/>
      </geometry>
      <origin xyz="0 0 0.008"/>
      <material name="clearpath_black"/>
    </visual>
  </link>
  <joint name="navsat_joint" type="fixed">
    <parent link="chassis_link"/>
    <child link="gps_0_link"/>
    <origin xyz="-0.180 0.126 0.1815"/>
  </joint>
  <gazebo reference="gps_0_link">
    <sensor name="gps_0" type="navsat">
      <always_on>1</always_on>
      <update_rate>10</update_rate>
      <gz_frame_id>gps_0_link</gz_frame_id>
      <topic>/sensors/gps_0/navsat</topic>
    </sensor>
  </gazebo>
  <link name="default_mount"/>
  <joint name="default_mount_joint" type="fixed">
    <parent link="chassis_link"/>
    <child link="default_mount"/>
    <origin xyz="0 0 0.184"/>
  </joint>
  <link name="rear_0_mount"/>
  <joint name="rear_0_mount_joint" type="fixed">
    <parent link="default_mount"/>
    <child link="rear_0_mount"/>
    <origin xyz="-0.12 0 0"/>
  </joint>
  <link name="front_0_mount"/>
  <joint name="front_0_mount_joint" type="fixed">
    <parent link="default_mount"/>
    <child link="front_0_mount"/>
    <origin xyz="0.12 0 0"/>
  </joint>
  <!-- AR4 Mount Plate -->
  <link name="ar4_mount_plate">
    <visual>
      <origin rpy="0 0 0" xyz="0 0 0"/>
      <geometry>
        <box size="0.2 0.2 0.01"/>
      </geometry>
      <material name="clearpath_black"/>
    </visual>
    <collision>
      <origin rpy="0 0 0" xyz="0 0 0"/>
      <geometry>
        <box size="0.2 0.2 0.01"/>
      </geometry>
    </collision>
    <inertial>
      <mass value="0.5"/>
      <origin rpy="0 0 0" xyz="0 0 0"/>
      <inertia ixx="0.002" ixy="0.0" ixz="0.0" iyy="0.002" iyz="0.0" izz="0.003"/>
    </inertial>
  </link>
  <joint name="ar4_mount_joint" type="fixed">
    <parent link="default_mount"/>
    <child link="ar4_mount_plate"/>
    <origin rpy="0 0 0" xyz="0 0 0.005"/>
  </joint>
  <!-- ===================== Arm link xacro ================================== -->
  <material name="black">
    <color rgba="0.0 0.0 0.0 1.0"/>
  </material>
  <material name="blue">
    <color rgba="0.020 0.032 0.171 1.0"/>
  </material>
  <material name="white">
    <color rgba="0.631 0.665 0.831 1.0"/>
  </material>
  <material name="grey">
    <color rgba="0.5 0.5 0.5 1.0"/>
  </material>
  <!-- ===================== Box inertia xacro ================================== -->
  <!-- params -->
  <!-- - m [float] link mass; -->
  <!-- - x [float] link dimension on the X-axis; -->
  <!-- - y [float] link dimension on the Y-axis; -->
  <!-- - z [float] link dimension on the Z-axis; -->
  <!-- - o_xyz [string] position offset -->
  <!-- - o_rpy [string] rotation offset -->
  <!-- ========================================================================== -->
  <link name="ar4_base_link">
    <origin rpy="0 0 0" xyz="0 0 0"/>
    <inertial>
      <mass value="0.7102"/>
      <inertia ixx="0.0007397916666666669" ixy="0.0" ixz="0.0" iyy="0.0035569183333333337" iyz="0.0" izz="0.004000793333333333"/>
      <origin rpy="0.0 0.0 0.0" xyz="-0.05 0.0 0.02"/>
    </inertial>
    <visual>
      <origin rpy="0.0 0.0 1.5708" xyz="0.0 0.0 0.0"/>
      <geometry>
        <mesh filename="package://ar4_description/meshes/base_link.stl"/>
      </geometry>
      <material name="grey"/>
    </visual>
    <collision>
      <origin rpy="0.0 0.0 1.5708" xyz="0.0 0.0 0.0"/>
      <geometry>
        <mesh filename="package://ar4_description/meshes/base_link.stl"/>
      </geometry>
    </collision>
    <visual>
      <origin rpy="0.0 0.0 1.5708" xyz="0.0 0.0 0.0"/>
      <geometry>
        <mesh filename="package://ar4_description/meshes/base_link_bottom.stl"/>
      </geometry>
      <material name="blue"/>
    </visual>
    <collision>
      <origin rpy="0.0 0.0 1.5708" xyz="0.0 0.0 0.0"/>
      <geometry>
        <mesh filename="package://ar4_description/meshes/base_link_bottom.stl"/>
      </geometry>
    </collision>
    <visual>
      <origin rpy="0.0 0.0 1.5708" xyz="0.0 0.0 0.0"/>
      <geometry>
        <mesh filename="package://ar4_description/meshes/base_link_motor.stl"/>
      </geometry>
      <material name="black"/>
    </visual>
    <collision>
      <origin rpy="0.0 0.0 1.5708" xyz="0.0 0.0 0.0"/>
      <geometry>
        <mesh filename="package://ar4_description/meshes/base_link_motor.stl"/>
      </geometry>
    </collision>
  </link>
  <link name="ar4_link_1">
    <origin rpy="0 0 0" xyz="0 0 0"/>
    <inertial>
      <mass value="0.88065"/>
      <inertia ixx="0.003669375000000001" ixy="0.0" ixz="0.0" iyy="0.003669375000000001" iyz="0.0" izz="0.0014677500000000005"/>
      <origin rpy="0.610865 0.418879 0.0" xyz="0.04 -0.01 0.1"/>
    </inertial>
    <visual>
      <origin rpy="3.1415 0.0 1.5708" xyz="0.0 0.0 0.0"/>
      <geometry>
        <mesh filename="package://ar4_description/meshes/link_1.stl"/>
      </geometry>
      <material name="grey"/>
    </visual>
    <collision>
      <origin rpy="3.1415 0.0 1.5708" xyz="0.0 0.0 0.0"/>
      <geometry>
        <mesh filename="package://ar4_description/meshes/link_1.stl"/>
      </geometry>
    </collision>
    <visual>
      <origin rpy="3.1415 0.0 1.5708" xyz="0.0 0.0 0.0"/>
      <geometry>
        <mesh filename="package://ar4_description/meshes/link_1_motor.stl"/>
      </geometry>
      <material name="black"/>
    </visual>
    <collision>
      <origin rpy="3.1415 0.0 1.5708" xyz="0.0 0.0 0.0"/>
      <geometry>
        <mesh filename="package://ar4_description/meshes/link_1_motor.stl"/>
      </geometry>
    </collision>
  </link>
  <joint name="ar4_joint_1" type="revolute">
    <origin rpy="0 0 0" xyz="0 0 0"/>
    <parent link="ar4_base_link"/>
    <child link="ar4_link_1"/>
    <axis xyz="0 0 1"/>
    <limit effort="100" lower="-2.96705972839036" upper="2.96705972839036" velocity="0.5"/>
  </joint>
  <link name="ar4_link_2">
    <origin rpy="0 0 0" xyz="0 0 0"/>
    <inertial>
      <mass value="0.57738"/>
      <inertia ixx="0.0067168539999999995" ixy="0.0" ixz="0.0" iyy="0.0009623000000000001" iyz="0.0" izz="0.0067168539999999995"/>
      <origin rpy="0.0 0.0 0.0" xyz="0.0 -0.15 0.03"/>
    </inertial>
    <visual>
      <origin rpy="0.0 3.1415 0.0" xyz="0.0 0.0 0.0"/>
      <geometry>
        <mesh filename="package://ar4_description/meshes/link_2.stl"/>
      </geometry>
      <material name="grey"/>
    </visual>
    <collision>
      <origin rpy="0.0 3.1415 0.0" xyz="0.0 0.0 0.0"/>
      <geometry>
        <mesh filename="package://ar4_description/meshes/link_2.stl"/>
      </geometry>
    </collision>
    <visual>
      <origin rpy="0.0 3.1415 0.0" xyz="0.0 0.0 0.0"/>
      <geometry>
        <mesh filename="package://ar4_description/meshes/link_2_motor.stl"/>
      </geometry>
      <material name="black"/>
    </visual>
    <collision>
      <origin rpy="0.0 3.1415 0.0" xyz="0.0 0.0 0.0"/>
      <geometry>
        <mesh filename="package://ar4_description/meshes/link_2_motor.stl"/>
      </geometry>
    </collision>
    <visual>
      <origin rpy="0.0 3.1415 0.0" xyz="0.0 0.0 0.0"/>
      <geometry>
        <mesh filename="package://ar4_description/meshes/link_2_cover.stl"/>
      </geometry>
      <material name="white"/>
    </visual>
    <collision>
      <origin rpy="0.0 3.1415 0.0" xyz="0.0 0.0 0.0"/>
      <geometry>
        <mesh filename="package://ar4_description/meshes/link_2_cover.stl"/>
      </geometry>
    </collision>
    <visual>
      <origin rpy="0.0 3.1415 0.0" xyz="0.0 0.0 0.0"/>
      <geometry>
        <mesh filename="package://ar4_description/meshes/link_2_cover_logo.stl"/>
      </geometry>
      <material name="blue"/>
    </visual>
    <collision>
      <origin rpy="0.0 3.1415 0.0" xyz="0.0 0.0 0.0"/>
      <geometry>
        <mesh filename="package://ar4_description/meshes/link_2_cover_logo.stl"/>
      </geometry>
    </collision>
  </link>
  <joint name="ar4_joint_2" type="revolute">
    <origin rpy="-1.5708 0 0" xyz="0.0642 0 0.16977"/>
    <parent link="ar4_link_1"/>
    <child link="ar4_link_2"/>
    <axis xyz="0 0 1"/>
    <limit effort="100" lower="-0.7330382858376184" upper="1.5707963267948966" velocity="0.5"/>
  </joint>
  <link name="ar4_link_3">
    <origin rpy="0 0 0" xyz="0 0 0"/>
    <inertial>
      <mass value="0.1787"/>
      <inertia ixx="0.0002516691666666666" ixy="0.0" ixz="0.0" iyy="0.00018614583333333336" iyz="0.0" izz="0.00036335666666666665"/>
      <origin rpy="0.0 0.0 0.0" xyz="-0.01 0.0 0.0"/>
    </inertial>
    <visual>
      <origin rpy="3.1415 0.0 1.5708" xyz="0.0 0.0 0.0"/>
      <geometry>
        <mesh filename="package://ar4_description/meshes/link_3.stl"/>
      </geometry>
      <material name="grey"/>
    </visual>
    <collision>
      <origin rpy="3.1415 0.0 1.5708" xyz="0.0 0.0 0.0"/>
      <geometry>
        <mesh filename="package://ar4_description/meshes/link_3.stl"/>
      </geometry>
    </collision>
    <visual>
      <origin rpy="3.1415 0.0 1.5708" xyz="0.0 0.0 0.0"/>
      <geometry>
        <mesh filename="package://ar4_description/meshes/link_3_motor.stl"/>
      </geometry>
      <material name="black"/>
    </visual>
    <collision>
      <origin rpy="3.1415 0.0 1.5708" xyz="0.0 0.0 0.0"/>
      <geometry>
        <mesh filename="package://ar4_description/meshes/link_3_motor.stl"/>
      </geometry>
    </collision>
    <visual>
      <origin rpy="3.1415 0.0 1.5708" xyz="0.0 0.0 0.0"/>
      <geometry>
        <mesh filename="package://ar4_description/meshes/link_3_misc.stl"/>
      </geometry>
      <material name="black"/>
    </visual>
    <collision>
      <origin rpy="3.1415 0.0 1.5708" xyz="0.0 0.0 0.0"/>
      <geometry>
        <mesh filename="package://ar4_description/meshes/link_3_misc.stl"/>
      </geometry>
    </collision>
  </link>
  <joint name="ar4_joint_3" type="revolute">
    <origin rpy="0 0 -1.5708" xyz="0 -0.305 0"/>
    <parent link="ar4_link_2"/>
    <child link="ar4_link_3"/>
    <axis xyz="0 0 1"/>
    <limit effort="100" lower="-1.5533430342749532" upper="0.9075712110370513" velocity="0.5"/>
  </joint>
  <link name="ar4_link_4">
    <origin rpy="0 0 0" xyz="0 0 0"/>
    <inertial>
      <mass value="0.34936"/>
      <inertia ixx="0.003086013333333334" ixy="0.0" ixz="0.0" iyy="0.003086013333333334" iyz="0.0" izz="0.000209616"/>
      <origin rpy="0.0 0.0 0.0" xyz="0.0 0.0 0.08"/>
    </inertial>
    <visual>
      <origin rpy="0.0 3.1415 0.0" xyz="0.0 0.0 0.0"/>
      <geometry>
        <mesh filename="package://ar4_description/meshes/link_4.stl"/>
      </geometry>
      <material name="grey"/>
    </visual>
    <collision>
      <origin rpy="0.0 3.1415 0.0" xyz="0.0 0.0 0.0"/>
      <geometry>
        <mesh filename="package://ar4_description/meshes/link_4.stl"/>
      </geometry>
    </collision>
    <visual>
      <origin rpy="0.0 3.1415 0.0" xyz="0.0 0.0 0.0"/>
      <geometry>
        <mesh filename="package://ar4_description/meshes/link_4_motor.stl"/>
      </geometry>
      <material name="black"/>
    </visual>
    <collision>
      <origin rpy="0.0 3.1415 0.0" xyz="0.0 0.0 0.0"/>
      <geometry>
        <mesh filename="package://ar4_description/meshes/link_4_motor.stl"/>
      </geometry>
    </collision>
  </link>
  <joint name="ar4_joint_4" type="revolute">
    <origin rpy="-1.5708 0 0" xyz="0 0 0.0"/>
    <parent link="ar4_link_3"/>
    <child link="ar4_link_4"/>
    <axis xyz="0 0 1"/>
    <limit effort="100" lower="-2.8797932657906435" upper="2.8797932657906435" velocity="0.5"/>
  </joint>
  <link name="ar4_link_5">
    <origin rpy="0 0 0" xyz="0 0 0"/>
    <inertial>
      <mass value="0.11562"/>
      <inertia ixx="7.708e-05" ixy="0.0" ixz="0.0" iyy="0.000158014" iyz="0.0" izz="0.00011176600000000001"/>
      <origin rpy="0.0 0.0 0.0" xyz="0.0 0.0 0.0"/>
    </inertial>
    <visual>
      <origin rpy="0.0 -1.5708 0.0" xyz="0.0 0.0 0.0"/>
      <geometry>
        <mesh filename="package://ar4_description/meshes/link_5.stl"/>
      </geometry>
      <material name="grey"/>
    </visual>
    <collision>
      <origin rpy="0.0 -1.5708 0.0" xyz="0.0 0.0 0.0"/>
      <geometry>
        <mesh filename="package://ar4_description/meshes/link_5.stl"/>
      </geometry>
    </collision>
    <visual>
      <origin rpy="0.0 -1.5708 0.0" xyz="0.0 0.0 0.0"/>
      <geometry>
        <mesh filename="package://ar4_description/meshes/link_5_motor.stl"/>
      </geometry>
      <material name="black"/>
    </visual>
    <collision>
      <origin rpy="0.0 -1.5708 0.0" xyz="0.0 0.0 0.0"/>
      <geometry>
        <mesh filename="package://ar4_description/meshes/link_5_motor.stl"/>
      </geometry>
    </collision>
  </link>
  <joint name="ar4_joint_5" type="revolute">
    <origin rpy="1.5708 0 0" xyz="0 0 0.22263"/>
    <parent link="ar4_link_4"/>
    <child link="ar4_link_5"/>
    <axis xyz="0 0 1"/>
    <limit effort="100" lower="-1.8325957145940461" upper="1.8325957145940461" velocity="1.0"/>
  </joint>
  <link name="ar4_link_6">
    <origin rpy="0 0 0" xyz="0 0 0"/>
    <inertial>
      <mass value="0.013863"/>
      <inertia ixx="9.242000000000001e-07" ixy="0.0" ixz="0.0" iyy="2.3105e-06" iyz="0.0" izz="2.3105e-06"/>
      <origin rpy="0.0 0.0 0.0" xyz="0.0 0.0 -0.01"/>
    </inertial>
    <visual>
      <origin rpy="0.0 0.0 0.0" xyz="0.0 0.0 0.0"/>
      <geometry>
        <mesh filename="package://ar4_description/meshes/link_6.stl"/>
      </geometry>
      <material name="grey"/>
    </visual>
    <collision>
      <origin rpy="0.0 0.0 0.0" xyz="0.0 0.0 0.0"/>
      <geometry>
        <mesh filename="package://ar4_description/meshes/link_6.stl"/>
      </geometry>
    </collision>
  </link>
  <joint name="ar4_joint_6" type="revolute">
    <origin rpy="0 -1.5708 0" xyz="-0.03625 0 0"/>
    <parent link="ar4_link_5"/>
    <child link="ar4_link_6"/>
    <axis xyz="0 0 1"/>
    <limit effort="100" lower="-2.705260340591211" upper="2.705260340591211" velocity="1.0"/>
  </joint>
  <!-- Joint: Mount plate to AR4 base -->
  <joint name="mount_to_ar4_joint" type="fixed">
    <parent link="ar4_mount_plate"/>
    <child link="ar4_base_link"/>
    <origin rpy="0 0 0" xyz="0 0 0.005"/>
  </joint>
</robot>
